Watching for file changes with StatReloader
Watching for file changes with StatReloader
(0.003) b'SELECT @@SQL_AUTO_IS_NULL'; args=None
(0.001) b'SET SESSION TRANSACTION ISOLATION LEVEL READ COMMITTED'; args=None
(0.046) b'SHOW FULL TABLES'; args=None
(0.004) b'SELECT `django_migrations`.`app`, `django_migrations`.`name` FROM `django_migrations`'; args=()
Performing system checks...

System check identified no issues (0 silenced).
June 09, 2021 - 10:49:57
Django version 2.2.1, using settings 'demo.settings'
Starting development server at http://0.0.0.0:666/
Quit the server with CONTROL-C.
Exception in thread django-main-thread:
Traceback (most recent call last):
  File "/usr/local/python/lib/python3.7/site-packages/pymysql/connections.py", line 571, in connect
    **kwargs)
  File "/usr/local/python/lib/python3.7/socket.py", line 727, in create_connection
    raise err
  File "/usr/local/python/lib/python3.7/socket.py", line 716, in create_connection
    sock.connect(sa)
ConnectionRefusedError: [Errno 111] Connection refused

During handling of the above exception, another exception occurred:

Traceback (most recent call last):
  File "/usr/local/python/lib/python3.7/site-packages/django/db/backends/base/base.py", line 217, in ensure_connection
    self.connect()
  File "/usr/local/python/lib/python3.7/site-packages/django/db/backends/base/base.py", line 195, in connect
    self.connection = self.get_new_connection(conn_params)
  File "/usr/local/python/lib/python3.7/site-packages/django/db/backends/mysql/base.py", line 227, in get_new_connection
    return Database.connect(**conn_params)
  File "/usr/local/python/lib/python3.7/site-packages/pymysql/__init__.py", line 94, in Connect
    return Connection(*args, **kwargs)
  File "/usr/local/python/lib/python3.7/site-packages/pymysql/connections.py", line 327, in __init__
    self.connect()
  File "/usr/local/python/lib/python3.7/site-packages/pymysql/connections.py", line 619, in connect
    raise exc
pymysql.err.OperationalError: (2003, "Can't connect to MySQL server on '192.168.116.200' ([Errno 111] Connection refused)")

The above exception was the direct cause of the following exception:

Traceback (most recent call last):
  File "/usr/local/python/lib/python3.7/threading.py", line 917, in _bootstrap_inner
    self.run()
  File "/usr/local/python/lib/python3.7/threading.py", line 865, in run
    self._target(*self._args, **self._kwargs)
  File "/usr/local/python/lib/python3.7/site-packages/django/utils/autoreload.py", line 54, in wrapper
    fn(*args, **kwargs)
  File "/usr/local/python/lib/python3.7/site-packages/django/core/management/commands/runserver.py", line 120, in inner_run
    self.check_migrations()
  File "/usr/local/python/lib/python3.7/site-packages/django/core/management/base.py", line 453, in check_migrations
    executor = MigrationExecutor(connections[DEFAULT_DB_ALIAS])
  File "/usr/local/python/lib/python3.7/site-packages/django/db/migrations/executor.py", line 18, in __init__
    self.loader = MigrationLoader(self.connection)
  File "/usr/local/python/lib/python3.7/site-packages/django/db/migrations/loader.py", line 49, in __init__
    self.build_graph()
  File "/usr/local/python/lib/python3.7/site-packages/django/db/migrations/loader.py", line 212, in build_graph
    self.applied_migrations = recorder.applied_migrations()
  File "/usr/local/python/lib/python3.7/site-packages/django/db/migrations/recorder.py", line 73, in applied_migrations
    if self.has_table():
  File "/usr/local/python/lib/python3.7/site-packages/django/db/migrations/recorder.py", line 56, in has_table
    return self.Migration._meta.db_table in self.connection.introspection.table_names(self.connection.cursor())
  File "/usr/local/python/lib/python3.7/site-packages/django/db/backends/base/base.py", line 256, in cursor
    return self._cursor()
  File "/usr/local/python/lib/python3.7/site-packages/django/db/backends/base/base.py", line 233, in _cursor
    self.ensure_connection()
  File "/usr/local/python/lib/python3.7/site-packages/django/db/backends/base/base.py", line 217, in ensure_connection
    self.connect()
  File "/usr/local/python/lib/python3.7/site-packages/django/db/utils.py", line 89, in __exit__
    raise dj_exc_value.with_traceback(traceback) from exc_value
  File "/usr/local/python/lib/python3.7/site-packages/django/db/backends/base/base.py", line 217, in ensure_connection
    self.connect()
  File "/usr/local/python/lib/python3.7/site-packages/django/db/backends/base/base.py", line 195, in connect
    self.connection = self.get_new_connection(conn_params)
  File "/usr/local/python/lib/python3.7/site-packages/django/db/backends/mysql/base.py", line 227, in get_new_connection
    return Database.connect(**conn_params)
  File "/usr/local/python/lib/python3.7/site-packages/pymysql/__init__.py", line 94, in Connect
    return Connection(*args, **kwargs)
  File "/usr/local/python/lib/python3.7/site-packages/pymysql/connections.py", line 327, in __init__
    self.connect()
  File "/usr/local/python/lib/python3.7/site-packages/pymysql/connections.py", line 619, in connect
    raise exc
django.db.utils.OperationalError: (2003, "Can't connect to MySQL server on '192.168.116.200' ([Errno 111] Connection refused)")

/xue/demo/blog/views.py changed, reloading.
Performing system checks...

System check identified no issues (0 silenced).
